[2024-04-24 18:00:44,039] 1758 asyncio - ERROR - Task exception was never retrieved
future: <Task finished name='Task-37' coro=<WebSocketProtocol13.write_message.<locals>.wrapper() done, defined at /opt/anaconda3/envs/mk-llm/lib/python3.10/site-packages/tornado/websocket.py:1086> exception=WebSocketClosedError()>
Traceback (most recent call last):
  File "/opt/anaconda3/envs/mk-llm/lib/python3.10/site-packages/tornado/websocket.py", line 1088, in wrapper
    await fut
tornado.iostream.StreamClosedError: Stream is closed

During handling of the above exception, another exception occurred:

Traceback (most recent call last):
  File "/opt/anaconda3/envs/mk-llm/lib/python3.10/site-packages/tornado/websocket.py", line 1090, in wrapper
    raise WebSocketClosedError()
tornado.websocket.WebSocketClosedError
